Workbook

Sheet 1_Data Entry
A1: Sale Tracker — Structured Workbook (App Revision v34)
A2: Manual entry tab. One row per buy lot. For partial sales, split into multiple rows. Column L is optional for manual replacement-lot override. Asset Description auto-fills from the reference table.
A5: Entry # | B5: Status | C5: Sleeve | D5: Asset Type | E5: Ticker | F5: Asset Description | G5: Buy Date | H5: Shares Bought | I5: Cost / Share | J5: Sell Date | K5: Shares Sold | L5: Sale Price / Share | M5: Shares Remaining | N5: Notes
A6: =IF($E6="","",IF(COUNTA(C6:N6)=0,"",ROW()-5)) -> 1 | B6: =IF(E6="","",IF(DataEntryTable[[#This Row],[Sell Date]]="","Open","Closed")) -> Closed | C6: =IF(E6="","",IFERROR(VLOOKUP(UPPER(TRIM(E6)),'6_Reference Lists'!$A$4:$D$64,2,FALSE()),"")) -> US | D6: =IF(E6="","",IFERROR(VLOOKUP(UPPER(TRIM(E6)),'6_Reference Lists'!$A$4:$D$64,3,FALSE()),"")) -> MLP | E6: EPD | F6: =IF(E6="","",IFERROR(VLOOKUP(UPPER(TRIM(E6)),'6_Reference Lists'!$A$4:$D$64,4,FALSE()),"")) -> Enterprise Products Partners L.P. | G6: 45338 | H6: 580 | I6: 27.25 | J6: 46090 | K6: 580 | L6: 38.15 | M6: =IF(E6="","",DataEntryTable[[#This Row],[Shares Bought]]-DataEntryTable[[#This Row],[Shares Sold]]) -> 0
A7: =IF($E7="","",IF(COUNTA(C7:N7)=0,"",ROW()-5)) -> 2 | B7: =IF(E7="","",IF(DataEntryTable[[#This Row],[Sell Date]]="","Open","Closed")) -> Closed | C7: =IF(E7="","",IFERROR(VLOOKUP(UPPER(TRIM(E7)),'6_Reference Lists'!$A$4:$D$64,2,FALSE()),"")) -> US | D7: =IF(E7="","",IFERROR(VLOOKUP(UPPER(TRIM(E7)),'6_Reference Lists'!$A$4:$D$64,3,FALSE()),"")) -> MLP | E7: EPD | F7: =IF(E7="","",IFERROR(VLOOKUP(UPPER(TRIM(E7)),'6_Reference Lists'!$A$4:$D$64,4,FALSE()),"")) -> Enterprise Products Partners L.P. | G7: 45338 | H7: 615 | I7: 27.25 | J7: 46090 | K7: 615 | L7: 38.15 | M7: =IF(E7="","",DataEntryTable[[#This Row],[Shares Bought]]-DataEntryTable[[#This Row],[Shares Sold]]) -> 0
A8: =IF($E8="","",IF(COUNTA(C8:N8)=0,"",ROW()-5)) -> 3 | B8: =IF(E8="","",IF(DataEntryTable[[#This Row],[Sell Date]]="","Open","Closed")) -> Closed | C8: =IF(E8="","",IFERROR(VLOOKUP(UPPER(TRIM(E8)),'6_Reference Lists'!$A$4:$D$64,2,FALSE()),"")) -> US | D8: =IF(E8="","",IFERROR(VLOOKUP(UPPER(TRIM(E8)),'6_Reference Lists'!$A$4:$D$64,3,FALSE()),"")) -> MLP | E8: EPD | F8: =IF(E8="","",IFERROR(VLOOKUP(UPPER(TRIM(E8)),'6_Reference Lists'!$A$4:$D$64,4,FALSE()),"")) -> Enterprise Products Partners L.P. | G8: 45706 | H8: 580 | I8: 33.72 | J8: 46090 | K8: 580 | L8: 38.15 | M8: =IF(E8="","",DataEntryTable[[#This Row],[Shares Bought]]-DataEntryTable[[#This Row],[Shares Sold]]) -> 0
A9: =IF($E9="","",IF(COUNTA(C9:N9)=0,"",ROW()-5)) -> 4 | B9: =IF(E9="","",IF(DataEntryTable[[#This Row],[Sell Date]]="","Open","Closed")) -> Closed | C9: =IF(E9="","",IFERROR(VLOOKUP(UPPER(TRIM(E9)),'6_Reference Lists'!$A$4:$D$64,2,FALSE()),"")) -> US | D9: =IF(E9="","",IFERROR(VLOOKUP(UPPER(TRIM(E9)),'6_Reference Lists'!$A$4:$D$64,3,FALSE()),"")) -> MLP | E9: EPD | F9: =IF(E9="","",IFERROR(VLOOKUP(UPPER(TRIM(E9)),'6_Reference Lists'!$A$4:$D$64,4,FALSE()),"")) -> Enterprise Products Partners L.P. | G9: 45706 | H9: 30 | I9: 33.72 | J9: 46090 | K9: 30 | L9: 38 | M9: =IF(E9="","",DataEntryTable[[#This Row],[Shares Bought]]-DataEntryTable[[#This Row],[Shares Sold]]) -> 0
A10: =IF($E10="","",IF(COUNTA(C10:N10)=0,"",ROW()-5)) -> 5 | B10: =IF(E10="","",IF(DataEntryTable[[#This Row],[Sell Date]]="","Open","Closed")) -> Closed | C10: =IF(E10="","",IFERROR(VLOOKUP(UPPER(TRIM(E10)),'6_Reference Lists'!$A$4:$D$64,2,FALSE()),"")) -> US | D10: =IF(E10="","",IFERROR(VLOOKUP(UPPER(TRIM(E10)),'6_Reference Lists'!$A$4:$D$64,3,FALSE()),"")) -> MLP | E10: EPD | F10: =IF(E10="","",IFERROR(VLOOKUP(UPPER(TRIM(E10)),'6_Reference Lists'!$A$4:$D$64,4,FALSE()),"")) -> Enterprise Products Partners L.P. | G10: 45706 | H10: 585 | I10: 33.72 | J10: 46090 | K10: 585 | L10: 38 | M10: =IF(E10="","",DataEntryTable[[#This Row],[Shares Bought]]-DataEntryTable[[#This Row],[Shares Sold]]) -> 0
A11: =IF($E11="","",IF(COUNTA(C11:N11)=0,"",ROW()-5)) -> 6 | B11: =IF(E11="","",IF(DataEntryTable[[#This Row],[Sell Date]]="","Open","Closed")) -> Closed | C11: =IF(E11="","",IFERROR(VLOOKUP(UPPER(TRIM(E11)),'6_Reference Lists'!$A$4:$D$64,2,FALSE()),"")) -> US | D11: =IF(E11="","",IFERROR(VLOOKUP(UPPER(TRIM(E11)),'6_Reference Lists'!$A$4:$D$64,3,FALSE()),"")) -> MLP | E11: EPD | F11: =IF(E11="","",IFERROR(VLOOKUP(UPPER(TRIM(E11)),'6_Reference Lists'!$A$4:$D$64,4,FALSE()),"")) -> Enterprise Products Partners L.P. | G11: 45706 | H11: 562 | I11: 33.72 | J11: 46090 | K11: 562 | L11: 38 | M11: =IF(E11="","",DataEntryTable[[#This Row],[Shares Bought]]-DataEntryTable[[#This Row],[Shares Sold]]) -> 0
A12: =IF($E12="","",IF(COUNTA(C12:N12)=0,"",ROW()-5)) -> 7 | B12: =IF(E12="","",IF(DataEntryTable[[#This Row],[Sell Date]]="","Open","Closed")) -> Closed | C12: =IF(E12="","",IFERROR(VLOOKUP(UPPER(TRIM(E12)),'6_Reference Lists'!$A$4:$D$64,2,FALSE()),"")) -> US | D12: =IF(E12="","",IFERROR(VLOOKUP(UPPER(TRIM(E12)),'6_Reference Lists'!$A$4:$D$64,3,FALSE()),"")) -> MLP | E12: EPD | F12: =IF(E12="","",IFERROR(VLOOKUP(UPPER(TRIM(E12)),'6_Reference Lists'!$A$4:$D$64,4,FALSE()),"")) -> Enterprise Products Partners L.P. | G12: 45706 | H12: 580 | I12: 33.72 | J12: 46090 | K12: 580 | L12: 38 | M12: =IF(E12="","",DataEntryTable[[#This Row],[Shares Bought]]-DataEntryTable[[#This Row],[Shares Sold]]) -> 0
A13: =IF($E13="","",IF(COUNTA(C13:N13)=0,"",ROW()-5)) -> 8 | B13: =IF(E13="","",IF(DataEntryTable[[#This Row],[Sell Date]]="","Open","Closed")) -> Closed | C13: =IF(E13="","",IFERROR(VLOOKUP(UPPER(TRIM(E13)),'6_Reference Lists'!$A$4:$D$64,2,FALSE()),"")) -> US | D13: =IF(E13="","",IFERROR(VLOOKUP(UPPER(TRIM(E13)),'6_Reference Lists'!$A$4:$D$64,3,FALSE()),"")) -> MLP | E13: EPD | F13: =IF(E13="","",IFERROR(VLOOKUP(UPPER(TRIM(E13)),'6_Reference Lists'!$A$4:$D$64,4,FALSE()),"")) -> Enterprise Products Partners L.P. | G13: 45338 | H13: 580 | I13: 27.25 | J13: 46098 | K13: 580 | L13: 37.79 | M13: =IF(E13="","",DataEntryTable[[#This Row],[Shares Bought]]-DataEntryTable[[#This Row],[Shares Sold]]) -> 0
A14: =IF($E14="","",IF(COUNTA(C14:N14)=0,"",ROW()-5)) -> 9 | B14: =IF(E14="","",IF(DataEntryTable[[#This Row],[Sell Date]]="","Open","Closed")) -> Closed | C14: =IF(E14="","",IFERROR(VLOOKUP(UPPER(TRIM(E14)),'6_Reference Lists'!$A$4:$D$64,2,FALSE()),"")) -> US | D14: =IF(E14="","",IFERROR(VLOOKUP(UPPER(TRIM(E14)),'6_Reference Lists'!$A$4:$D$64,3,FALSE()),"")) -> MLP | E14: EPD | F14: =IF(E14="","",IFERROR(VLOOKUP(UPPER(TRIM(E14)),'6_Reference Lists'!$A$4:$D$64,4,FALSE()),"")) -> Enterprise Products Partners L.P. | G14: 45338 | H14: 351 | I14: 27.25 | J14: 46098 | K14: 351 | L14: 37.79 | M14: =IF(E14="","",DataEntryTable[[#This Row],[Shares Bought]]-DataEntryTable[[#This Row],[Shares Sold]]) -> 0
A15: =IF($E15="","",IF(COUNTA(C15:N15)=0,"",ROW()-5)) -> 10 | B15: =IF(E15="","",IF(DataEntryTable[[#This Row],[Sell Date]]="","Open","Closed")) -> Closed | C15: =IF(E15="","",IFERROR(VLOOKUP(UPPER(TRIM(E15)),'6_Reference Lists'!$A$4:$D$64,2,FALSE()),"")) -> US | D15: =IF(E15="","",IFERROR(VLOOKUP(UPPER(TRIM(E15)),'6_Reference Lists'!$A$4:$D$64,3,FALSE()),"")) -> ETF | E15: ITOT | F15: =IF(E15="","",IFERROR(VLOOKUP(UPPER(TRIM(E15)),'6_Reference Lists'!$A$4:$D$64,4,FALSE()),"")) -> iShares Core S&P Total U.S. Stock Market ETF | G15: 46098 | H15: 0.883 | I15: 150.63 | J15: 46101 | K15: 0.883 | L15: 142.93 | M15: =IF(E15="","",DataEntryTable[[#This Row],[Shares Bought]]-DataEntryTable[[#This Row],[Shares Sold]]) -> 0
A16: =IF($E16="","",IF(COUNTA(C16:N16)=0,"",ROW()-5)) -> 11 | B16: =IF(E16="","",IF(DataEntryTable[[#This Row],[Sell Date]]="","Open","Closed")) -> Closed | C16: =IF(E16="","",IFERROR(VLOOKUP(UPPER(TRIM(E16)),'6_Reference Lists'!$A$4:$D$64,2,FALSE()),"")) -> US | D16: =IF(E16="","",IFERROR(VLOOKUP(UPPER(TRIM(E16)),'6_Reference Lists'!$A$4:$D$64,3,FALSE()),"")) -> ETF | E16: ITOT | F16: =IF(E16="","",IFERROR(VLOOKUP(UPPER(TRIM(E16)),'6_Reference Lists'!$A$4:$D$64,4,FALSE()),"")) -> iShares Core S&P Total U.S. Stock Market ETF | G16: 46098 | H16: 143 | I16: 146.76 | J16: 46101 | K16: 143 | L16: 142.93 | M16: =IF(E16="","",DataEntryTable[[#This Row],[Shares Bought]]-DataEntryTable[[#This Row],[Shares Sold]]) -> 0
A17: =IF($E17="","",IF(COUNTA(C17:N17)=0,"",ROW()-5)) -> 12 | B17: =IF(E17="","",IF(DataEntryTable[[#This Row],[Sell Date]]="","Open","Closed")) -> Closed | C17: =IF(E17="","",IFERROR(VLOOKUP(UPPER(TRIM(E17)),'6_Reference Lists'!$A$4:$D$64,2,FALSE()),"")) -> US | D17: =IF(E17="","",IFERROR(VLOOKUP(UPPER(TRIM(E17)),'6_Reference Lists'!$A$4:$D$64,3,FALSE()),"")) -> ETF | E17: SCHB | F17: =IF(E17="","",IFERROR(VLOOKUP(UPPER(TRIM(E17)),'6_Reference Lists'!$A$4:$D$64,4,FALSE()),"")) -> Schwab U.S. Broad Market ETF | G17: 46098 | H17: 0.872 | I17: 25.951835 | J17: 46108 | K17: 0.872 | L17: 24.610092 | M17: =IF(E17="","",DataEntryTable[[#This Row],[Shares Bought]]-DataEntryTable[[#This Row],[Shares Sold]]) -> 0
A18: =IF($E18="","",IF(COUNTA(C18:N18)=0,"",ROW()-5)) -> 13 | B18: =IF(E18="","",IF(DataEntryTable[[#This Row],[Sell Date]]="","Open","Closed")) -> Closed | C18: =IF(E18="","",IFERROR(VLOOKUP(UPPER(TRIM(E18)),'6_Reference Lists'!$A$4:$D$64,2,FALSE()),"")) -> US | D18: =IF(E18="","",IFERROR(VLOOKUP(UPPER(TRIM(E18)),'6_Reference Lists'!$A$4:$D$64,3,FALSE()),"")) -> ETF | E18: SCHB | F18: =IF(E18="","",IFERROR(VLOOKUP(UPPER(TRIM(E18)),'6_Reference Lists'!$A$4:$D$64,4,FALSE()),"")) -> Schwab U.S. Broad Market ETF | G18: 46098 | H18: 813 | I18: 25.95 | J18: 46108 | K18: 813 | L18: 24.600295 | M18: =IF(E18="","",DataEntryTable[[#This Row],[Shares Bought]]-DataEntryTable[[#This Row],[Shares Sold]]) -> 0
A19: =IF($E19="","",IF(COUNTA(C19:N19)=0,"",ROW()-5)) -> 14 | B19: =IF(E19="","",IF(DataEntryTable[[#This Row],[Sell Date]]="","Open","Closed")) -> Closed | C19: =IF(E19="","",IFERROR(VLOOKUP(UPPER(TRIM(E19)),'6_Reference Lists'!$A$4:$D$64,2,FALSE()),"")) -> US | D19: =IF(E19="","",IFERROR(VLOOKUP(UPPER(TRIM(E19)),'6_Reference Lists'!$A$4:$D$64,3,FALSE()),"")) -> MLP | E19: EPD | F19: =IF(E19="","",IFERROR(VLOOKUP(UPPER(TRIM(E19)),'6_Reference Lists'!$A$4:$D$64,4,FALSE()),"")) -> Enterprise Products Partners L.P. | G19: 45960 | H19: 800 | I19: 30.53 | J19: 46111 | K19: 800 | L19: 39.05 | M19: =IF(E19="","",DataEntryTable[[#This Row],[Shares Bought]]-DataEntryTable[[#This Row],[Shares Sold]]) -> 0 | N19: Sold 800 shares @ 39.05; combined two same-day fills of 400 shares each.
A20: =IF($E20="","",IF(COUNTA(C20:N20)=0,"",ROW()-5)) -> 15 | B20: =IF(E20="","",IF(DataEntryTable[[#This Row],[Sell Date]]="","Open","Closed")) -> Open | C20: =IF(E20="","",IFERROR(VLOOKUP(UPPER(TRIM(E20)),'6_Reference Lists'!$A$4:$D$64,2,FALSE()),"")) -> US | D20: =IF(E20="","",IFERROR(VLOOKUP(UPPER(TRIM(E20)),'6_Reference Lists'!$A$4:$D$64,3,FALSE()),"")) -> ETF | E20: VTI | F20: =IF(E20="","",IFERROR(VLOOKUP(UPPER(TRIM(E20)),'6_Reference Lists'!$A$4:$D$64,4,FALSE()),"")) -> Vanguard Total Stock Market ETF | G20: 46098 | H20: 0.251 | I20: 331.83267 | K20: 0 | M20: =IF(E20="","",DataEntryTable[[#This Row],[Shares Bought]]-DataEntryTable[[#This Row],[Shares Sold]]) -> 0.251
A21: =IF($E21="","",IF(COUNTA(C21:N21)=0,"",ROW()-5)) -> 16 | B21: =IF(E21="","",IF(DataEntryTable[[#This Row],[Sell Date]]="","Open","Closed")) -> Open | C21: =IF(E21="","",IFERROR(VLOOKUP(UPPER(TRIM(E21)),'6_Reference Lists'!$A$4:$D$64,2,FALSE()),"")) -> US | D21: =IF(E21="","",IFERROR(VLOOKUP(UPPER(TRIM(E21)),'6_Reference Lists'!$A$4:$D$64,3,FALSE()),"")) -> ETF | E21: VTI | F21: =IF(E21="","",IFERROR(VLOOKUP(UPPER(TRIM(E21)),'6_Reference Lists'!$A$4:$D$64,4,FALSE()),"")) -> Vanguard Total Stock Market ETF | G21: 46098 | H21: 212 | I21: 331.8 | K21: 0 | M21: =IF(E21="","",DataEntryTable[[#This Row],[Shares Bought]]-DataEntryTable[[#This Row],[Shares Sold]]) -> 212
A22: =IF($E22="","",IF(COUNTA(C22:N22)=0,"",ROW()-5)) -> 17 | B22: =IF(E22="","",IF(DataEntryTable[[#This Row],[Sell Date]]="","Open","Closed")) -> Open | C22: =IF(E22="","",IFERROR(VLOOKUP(UPPER(TRIM(E22)),'6_Reference Lists'!$A$4:$D$64,2,FALSE()),"")) -> US | D22: =IF(E22="","",IFERROR(VLOOKUP(UPPER(TRIM(E22)),'6_Reference Lists'!$A$4:$D$64,3,FALSE()),"")) -> ETF | E22: VOO | F22: =IF(E22="","",IFERROR(VLOOKUP(UPPER(TRIM(E22)),'6_Reference Lists'!$A$4:$D$64,4,FALSE()),"")) -> Vanguard S&P 500 ETF | G22: 46099 | H22: 0.993 | I22: 614.73313 | K22: 0 | M22: =IF(E22="","",DataEntryTable[[#This Row],[Shares Bought]]-DataEntryTable[[#This Row],[Shares Sold]]) -> 0.993
A23: =IF($E23="","",IF(COUNTA(C23:N23)=0,"",ROW()-5)) -> 18 | B23: =IF(E23="","",IF(DataEntryTable[[#This Row],[Sell Date]]="","Open","Closed")) -> Open | C23: =IF(E23="","",IFERROR(VLOOKUP(UPPER(TRIM(E23)),'6_Reference Lists'!$A$4:$D$64,2,FALSE()),"")) -> US | D23: =IF(E23="","",IFERROR(VLOOKUP(UPPER(TRIM(E23)),'6_Reference Lists'!$A$4:$D$64,3,FALSE()),"")) -> ETF | E23: VOO | F23: =IF(E23="","",IFERROR(VLOOKUP(UPPER(TRIM(E23)),'6_Reference Lists'!$A$4:$D$64,4,FALSE()),"")) -> Vanguard S&P 500 ETF | G23: 46099 | H23: 40 | I23: 614.735 | K23: 0 | M23: =IF(E23="","",DataEntryTable[[#This Row],[Shares Bought]]-DataEntryTable[[#This Row],[Shares Sold]]) -> 40
A24: =IF($E24="","",IF(COUNTA(C24:N24)=0,"",ROW()-5)) -> 19 | B24: =IF(E24="","",IF(DataEntryTable[[#This Row],[Sell Date]]="","Open","Closed")) -> Open | C24: =IF(E24="","",IFERROR(VLOOKUP(UPPER(TRIM(E24)),'6_Reference Lists'!$A$4:$D$64,2,FALSE()),"")) -> US | D24: =IF(E24="","",IFERROR(VLOOKUP(UPPER(TRIM(E24)),'6_Reference Lists'!$A$4:$D$64,3,FALSE()),"")) -> ETF | E24: VOO | F24: =IF(E24="","",IFERROR(VLOOKUP(UPPER(TRIM(E24)),'6_Reference Lists'!$A$4:$D$64,4,FALSE()),"")) -> Vanguard S&P 500 ETF | G24: 46101 | H24: 34 | I24: 602.785 | K24: 0 | M24: =IF(E24="","",DataEntryTable[[#This Row],[Shares Bought]]-DataEntryTable[[#This Row],[Shares Sold]]) -> 34
A25: =IF($E25="","",IF(COUNTA(C25:N25)=0,"",ROW()-5)) -> 20 | B25: =IF(E25="","",IF(DataEntryTable[[#This Row],[Sell Date]]="","Open","Closed")) -> Open | C25: =IF(E25="","",IFERROR(VLOOKUP(UPPER(TRIM(E25)),'6_Reference Lists'!$A$4:$D$64,2,FALSE()),"")) -> US | D25: =IF(E25="","",IFERROR(VLOOKUP(UPPER(TRIM(E25)),'6_Reference Lists'!$A$4:$D$64,3,FALSE()),"")) -> ETF | E25: VOO | F25: =IF(E25="","",IFERROR(VLOOKUP(UPPER(TRIM(E25)),'6_Reference Lists'!$A$4:$D$64,4,FALSE()),"")) -> Vanguard S&P 500 ETF | G25: 46101 | H25: 0.135 | I25: 602.81481 | K25: 0 | M25: =IF(E25="","",DataEntryTable[[#This Row],[Shares Bought]]-DataEntryTable[[#This Row],[Shares Sold]]) -> 0.135
A26: =IF($E26="","",IF(COUNTA(C26:N26)=0,"",ROW()-5)) -> 21 | B26: =IF(E26="","",IF(DataEntryTable[[#This Row],[Sell Date]]="","Open","Closed")) -> Open | C26: =IF(E26="","",IFERROR(VLOOKUP(UPPER(TRIM(E26)),'6_Reference Lists'!$A$4:$D$64,2,FALSE()),"")) -> US | D26: =IF(E26="","",IFERROR(VLOOKUP(UPPER(TRIM(E26)),'6_Reference Lists'!$A$4:$D$64,3,FALSE()),"")) -> ETF | E26: VTI | F26: =IF(E26="","",IFERROR(VLOOKUP(UPPER(TRIM(E26)),'6_Reference Lists'!$A$4:$D$64,4,FALSE()),"")) -> Vanguard Total Stock Market ETF | G26: 46108 | H26: 0.736 | I26: 314.34783 | K26: 0 | M26: =IF(E26="","",DataEntryTable[[#This Row],[Shares Bought]]-DataEntryTable[[#This Row],[Shares Sold]]) -> 0.736
A27: =IF($E27="","",IF(COUNTA(C27:N27)=0,"",ROW()-5)) -> 22 | B27: =IF(E27="","",IF(DataEntryTable[[#This Row],[Sell Date]]="","Open","Closed")) -> Open | C27: =IF(E27="","",IFERROR(VLOOKUP(UPPER(TRIM(E27)),'6_Reference Lists'!$A$4:$D$64,2,FALSE()),"")) -> US | D27: =IF(E27="","",IFERROR(VLOOKUP(UPPER(TRIM(E27)),'6_Reference Lists'!$A$4:$D$64,3,FALSE()),"")) -> ETF | E27: VTI | F27: =IF(E27="","",IFERROR(VLOOKUP(UPPER(TRIM(E27)),'6_Reference Lists'!$A$4:$D$64,4,FALSE()),"")) -> Vanguard Total Stock Market ETF | G27: 46108 | H27: 63 | I27: 314.35 | K27: 0 | M27: =IF(E27="","",DataEntryTable[[#This Row],[Shares Bought]]-DataEntryTable[[#This Row],[Shares Sold]]) -> 63
A28: =IF($E28="","",IF(COUNTA(C28:N28)=0,"",ROW()-5)) -> 23 | B28: =IF(E28="","",IF(DataEntryTable[[#This Row],[Sell Date]]="","Open","Closed")) -> Closed | C28: =IF(E28="","",IFERROR(VLOOKUP(UPPER(TRIM(E28)),'6_Reference Lists'!$A$4:$D$64,2,FALSE()),"")) -> International | D28: =IF(E28="","",IFERROR(VLOOKUP(UPPER(TRIM(E28)),'6_Reference Lists'!$A$4:$D$64,3,FALSE()),"")) -> ETF | E28: IXUS | F28: =IF(E28="","",IFERROR(VLOOKUP(UPPER(TRIM(E28)),'6_Reference Lists'!$A$4:$D$64,4,FALSE()),"")) -> iShares Core MSCI Total International Stock ETF | G28: 46098 | H28: 157.003 | I28: 88.55 | J28: 46101 | K28: 157.003 | L28: 83.55 | M28: =IF(E28="","",DataEntryTable[[#This Row],[Shares Bought]]-DataEntryTable[[#This Row],[Shares Sold]]) -> 0
A29: =IF($E29="","",IF(COUNTA(C29:N29)=0,"",ROW()-5)) -> 24 | B29: =IF(E29="","",IF(DataEntryTable[[#This Row],[Sell Date]]="","Open","Closed")) -> Closed | C29: =IF(E29="","",IFERROR(VLOOKUP(UPPER(TRIM(E29)),'6_Reference Lists'!$A$4:$D$64,2,FALSE()),"")) -> International | D29: =IF(E29="","",IFERROR(VLOOKUP(UPPER(TRIM(E29)),'6_Reference Lists'!$A$4:$D$64,3,FALSE()),"")) -> ETF | E29: IXUS | F29: =IF(E29="","",IFERROR(VLOOKUP(UPPER(TRIM(E29)),'6_Reference Lists'!$A$4:$D$64,4,FALSE()),"")) -> iShares Core MSCI Total International Stock ETF | G29: 46098 | H29: 0.997 | I29: 93.56 | J29: 46101 | K29: 0.997 | L29: 83.55 | M29: =IF(E29="","",DataEntryTable[[#This Row],[Shares Bought]]-DataEntryTable[[#This Row],[Shares Sold]]) -> 0
A30: =IF($E30="","",IF(COUNTA(C30:N30)=0,"",ROW()-5)) -> 25 | B30: =IF(E30="","",IF(DataEntryTable[[#This Row],[Sell Date]]="","Open","Closed")) -> Open | C30: =IF(E30="","",IFERROR(VLOOKUP(UPPER(TRIM(E30)),'6_Reference Lists'!$A$4:$D$64,2,FALSE()),"")) -> International | D30: =IF(E30="","",IFERROR(VLOOKUP(UPPER(TRIM(E30)),'6_Reference Lists'!$A$4:$D$64,3,FALSE()),"")) -> ETF | E30: VXUS | F30: =IF(E30="","",IFERROR(VLOOKUP(UPPER(TRIM(E30)),'6_Reference Lists'!$A$4:$D$64,4,FALSE()),"")) -> Vanguard Total International Stock ETF | G30: 46098 | H30: 178 | I30: 79.019888 | K30: 0 | M30: =IF(E30="","",DataEntryTable[[#This Row],[Shares Bought]]-DataEntryTable[[#This Row],[Shares Sold]]) -> 178
A31: =IF($E31="","",IF(COUNTA(C31:N31)=0,"",ROW()-5)) -> 26 | B31: =IF(E31="","",IF(DataEntryTable[[#This Row],[Sell Date]]="","Open","Closed")) -> Open | C31: =IF(E31="","",IFERROR(VLOOKUP(UPPER(TRIM(E31)),'6_Reference Lists'!$A$4:$D$64,2,FALSE()),"")) -> International | D31: =IF(E31="","",IFERROR(VLOOKUP(UPPER(TRIM(E31)),'6_Reference Lists'!$A$4:$D$64,3,FALSE()),"")) -> ETF | E31: VXUS | F31: =IF(E31="","",IFERROR(VLOOKUP(UPPER(TRIM(E31)),'6_Reference Lists'!$A$4:$D$64,4,FALSE()),"")) -> Vanguard Total International Stock ETF | G31: 46098 | H31: 0.182 | I31: 79.010989 | K31: 0 | M31: =IF(E31="","",DataEntryTable[[#This Row],[Shares Bought]]-DataEntryTable[[#This Row],[Shares Sold]]) -> 0.182
A32: =IF($E32="","",IF(COUNTA(C32:N32)=0,"",ROW()-5)) -> 27 | B32: =IF(E32="","",IF(DataEntryTable[[#This Row],[Sell Date]]="","Open","Closed")) -> Open | C32: =IF(E32="","",IFERROR(VLOOKUP(UPPER(TRIM(E32)),'6_Reference Lists'!$A$4:$D$64,2,FALSE()),"")) -> International | D32: =IF(E32="","",IFERROR(VLOOKUP(UPPER(TRIM(E32)),'6_Reference Lists'!$A$4:$D$64,3,FALSE()),"")) -> ETF | E32: VXUS | F32: =IF(E32="","",IFERROR(VLOOKUP(UPPER(TRIM(E32)),'6_Reference Lists'!$A$4:$D$64,4,FALSE()),"")) -> Vanguard Total International Stock ETF | G32: 46101 | H32: 177 | I32: 74.639887 | K32: 0 | M32: =IF(E32="","",DataEntryTable[[#This Row],[Shares Bought]]-DataEntryTable[[#This Row],[Shares Sold]]) -> 177
A33: =IF($E33="","",IF(COUNTA(C33:N33)=0,"",ROW()-5)) -> 28 | B33: =IF(E33="","",IF(DataEntryTable[[#This Row],[Sell Date]]="","Open","Closed")) -> Open | C33: =IF(E33="","",IFERROR(VLOOKUP(UPPER(TRIM(E33)),'6_Reference Lists'!$A$4:$D$64,2,FALSE()),"")) -> International | D33: =IF(E33="","",IFERROR(VLOOKUP(UPPER(TRIM(E33)),'6_Reference Lists'!$A$4:$D$64,3,FALSE()),"")) -> ETF | E33: VXUS | F33: =IF(E33="","",IFERROR(VLOOKUP(UPPER(TRIM(E33)),'6_Reference Lists'!$A$4:$D$64,4,FALSE()),"")) -> Vanguard Total International Stock ETF | G33: 46101 | H33: 0.98 | I33: 74.632653 | K33: 0 | M33: =IF(E33="","",DataEntryTable[[#This Row],[Shares Bought]]-DataEntryTable[[#This Row],[Shares Sold]]) -> 0.98
A34: =IF($E34="","",IF(COUNTA(C34:N34)=0,"",ROW()-5)) -> 29 | B34: =IF(E34="","",IF(DataEntryTable[[#This Row],[Sell Date]]="","Open","Closed")) -> Closed | C34: =IF(E34="","",IFERROR(VLOOKUP(UPPER(TRIM(E34)),'6_Reference Lists'!$A$4:$D$64,2,FALSE()),"")) -> US | D34: =IF(E34="","",IFERROR(VLOOKUP(UPPER(TRIM(E34)),'6_Reference Lists'!$A$4:$D$64,3,FALSE()),"")) -> MLP | E34: EPD | F34: =IF(E34="","",IFERROR(VLOOKUP(UPPER(TRIM(E34)),'6_Reference Lists'!$A$4:$D$64,4,FALSE()),"")) -> Enterprise Products Partners L.P. | G34: 45960 | H34: 310 | I34: 30.53 | J34: 46111 | K34: 310 | L34: 39.0514 | M34: =IF(E34="","",DataEntryTable[[#This Row],[Shares Bought]]-DataEntryTable[[#This Row],[Shares Sold]]) -> 0 | N34: Sold 310 shares @ 39.0514; separate same-day execution.
A35: =IF($E35="","",IF(COUNTA(C35:N35)=0,"",ROW()-5)) -> 30 | B35: =IF(E35="","",IF(DataEntryTable[[#This Row],[Sell Date]]="","Open","Closed")) -> Open | C35: =IF(E35="","",IFERROR(VLOOKUP(UPPER(TRIM(E35)),'6_Reference Lists'!$A$4:$D$64,2,FALSE()),"")) -> US | D35: =IF(E35="","",IFERROR(VLOOKUP(UPPER(TRIM(E35)),'6_Reference Lists'!$A$4:$D$64,3,FALSE()),"")) -> ETF | E35: schb | F35: =IF(E35="","",IFERROR(VLOOKUP(UPPER(TRIM(E35)),'6_Reference Lists'!$A$4:$D$64,4,FALSE()),"")) -> Schwab U.S. Broad Market ETF | G35: 46111 | H35: 50 | I35: 20 | M35: =IF(E35="","",DataEntryTable[[#This Row],[Shares Bought]]-DataEntryTable[[#This Row],[Shares Sold]]) -> 50
A36: =IF($E36="","",IF(COUNTA(C36:N36)=0,"",ROW()-5)) -> 31 | B36: =IF(E36="","",IF(DataEntryTable[[#This Row],[Sell Date]]="","Open","Closed")) -> Open | C36: =IF(E36="","",IFERROR(VLOOKUP(UPPER(TRIM(E36)),'6_Reference Lists'!$A$4:$D$64,2,FALSE()),"")) -> US | D36: =IF(E36="","",IFERROR(VLOOKUP(UPPER(TRIM(E36)),'6_Reference Lists'!$A$4:$D$64,3,FALSE()),"")) -> ETF | E36: schb | F36: =IF(E36="","",IFERROR(VLOOKUP(UPPER(TRIM(E36)),'6_Reference Lists'!$A$4:$D$64,4,FALSE()),"")) -> Schwab U.S. Broad Market ETF | G36: 46112 | H36: 60 | I36: 22 | M36: =IF(E36="","",DataEntryTable[[#This Row],[Shares Bought]]-DataEntryTable[[#This Row],[Shares Sold]]) -> 60
A37: =IF($E37="","",IF(COUNTA(C37:N37)=0,"",ROW()-5)) -> 32 | B37: =IF(E37="","",IF(DataEntryTable[[#This Row],[Sell Date]]="","Open","Closed")) -> Open | C37: =IF(E37="","",IFERROR(VLOOKUP(UPPER(TRIM(E37)),'6_Reference Lists'!$A$4:$D$64,2,FALSE()),"")) -> US | D37: =IF(E37="","",IFERROR(VLOOKUP(UPPER(TRIM(E37)),'6_Reference Lists'!$A$4:$D$64,3,FALSE()),"")) -> ETF | E37: schb | F37: =IF(E37="","",IFERROR(VLOOKUP(UPPER(TRIM(E37)),'6_Reference Lists'!$A$4:$D$64,4,FALSE()),"")) -> Schwab U.S. Broad Market ETF | G37: 46133 | H37: 70 | I37: 24 | M37: =IF(E37="","",DataEntryTable[[#This Row],[Shares Bought]]-DataEntryTable[[#This Row],[Shares Sold]]) -> 70
A38: =IF($E38="","",IF(COUNTA(C38:N38)=0,"",ROW()-5)) | B38: =IF(E38="","",IF(DataEntryTable[[#This Row],[Sell Date]]="","Open","Closed")) | C38: =IF(E38="","",IFERROR(VLOOKUP(UPPER(TRIM(E38)),'6_Reference Lists'!$A$4:$D$64,2,FALSE()),"")) | D38: =IF(E38="","",IFERROR(VLOOKUP(UPPER(TRIM(E38)),'6_Reference Lists'!$A$4:$D$64,3,FALSE()),"")) | F38: =IF(E38="","",IFERROR(VLOOKUP(UPPER(TRIM(E38)),'6_Reference Lists'!$A$4:$D$64,4,FALSE()),"")) | M38: =IF(E38="","",DataEntryTable[[#This Row],[Shares Bought]]-DataEntryTable[[#This Row],[Shares Sold]])
A39: =IF($E39="","",IF(COUNTA(C39:N39)=0,"",ROW()-5)) | B39: =IF(E39="","",IF(DataEntryTable[[#This Row],[Sell Date]]="","Open","Closed")) | C39: =IF(E39="","",IFERROR(VLOOKUP(UPPER(TRIM(E39)),'6_Reference Lists'!$A$4:$D$64,2,FALSE()),"")) | D39: =IF(E39="","",IFERROR(VLOOKUP(UPPER(TRIM(E39)),'6_Reference Lists'!$A$4:$D$64,3,FALSE()),"")) | F39: =IF(E39="","",IFERROR(VLOOKUP(UPPER(TRIM(E39)),'6_Reference Lists'!$A$4:$D$64,4,FALSE()),"")) | M39: =IF(E39="","",DataEntryTable[[#This Row],[Shares Bought]]-DataEntryTable[[#This Row],[Shares Sold]])
A40: =IF($E40="","",IF(COUNTA(C40:N40)=0,"",ROW()-5)) | B40: =IF(E40="","",IF(DataEntryTable[[#This Row],[Sell Date]]="","Open","Closed")) | C40: =IF(E40="","",IFERROR(VLOOKUP(UPPER(TRIM(E40)),'6_Reference Lists'!$A$4:$D$64,2,FALSE()),"")) | D40: =IF(E40="","",IFERROR(VLOOKUP(UPPER(TRIM(E40)),'6_Reference Lists'!$A$4:$D$64,3,FALSE()),"")) | F40: =IF(E40="","",IFERROR(VLOOKUP(UPPER(TRIM(E40)),'6_Reference Lists'!$A$4:$D$64,4,FALSE()),"")) | M40: =IF(E40="","",DataEntryTable[[#This Row],[Shares Bought]]-DataEntryTable[[#This Row],[Shares Sold]])
A41: =IF($E41="","",IF(COUNTA(C41:N41)=0,"",ROW()-5)) | B41: =IF(E41="","",IF(DataEntryTable[[#This Row],[Sell Date]]="","Open","Closed")) | C41: =IF(E41="","",IFERROR(VLOOKUP(UPPER(TRIM(E41)),'6_Reference Lists'!$A$4:$D$64,2,FALSE()),"")) | D41: =IF(E41="","",IFERROR(VLOOKUP(UPPER(TRIM(E41)),'6_Reference Lists'!$A$4:$D$64,3,FALSE()),"")) | F41: =IF(E41="","",IFERROR(VLOOKUP(UPPER(TRIM(E41)),'6_Reference Lists'!$A$4:$D$64,4,FALSE()),"")) | M41: =IF(E41="","",DataEntryTable[[#This Row],[Shares Bought]]-DataEntryTable[[#This Row],[Shares Sold]])
A42: =IF($E42="","",IF(COUNTA(C42:N42)=0,"",ROW()-5)) | B42: =IF(E42="","",IF(DataEntryTable[[#This Row],[Sell Date]]="","Open","Closed")) | C42: =IF(E42="","",IFERROR(VLOOKUP(UPPER(TRIM(E42)),'6_Reference Lists'!$A$4:$D$64,2,FALSE()),"")) | D42: =IF(E42="","",IFERROR(VLOOKUP(UPPER(TRIM(E42)),'6_Reference Lists'!$A$4:$D$64,3,FALSE()),"")) | F42: =IF(E42="","",IFERROR(VLOOKUP(UPPER(TRIM(E42)),'6_Reference Lists'!$A$4:$D$64,4,FALSE()),"")) | M42: =IF(E42="","",DataEntryTable[[#This Row],[Shares Bought]]-DataEntryTable[[#This Row],[Shares Sold]])
...

Sheet 2_Review & Audit
A1: 2_Review & Audit
A2: Cleaned helper layer for imported rows. Gray area = review outputs and current-state calculations.
A5: Entry # | B5: Data Entry Status | C5: Sleeve | D5: Asset Type | E5: Raw Ticker | F5: Clean Ticker | G5: Asset Description | H5: Generated Lot ID | I5: Buy Date | J5: Shares Bought | K5: Cost / Share | L5: Purchase Cost | M5: Sell Date | N5: Shares Sold | O5: Sale Price / Share | P5: Sale Proceeds | Q5: Realized Gain / (Loss) | R5: Shares Remaining | S5: Validation Flag | T5: Wash Candidate? | U5: Recent Rebuy? | V5: Wash Sale Window End Date | W5: Review Notes | X5: Holding Period (Days) | Y5: Tax Term | Z5: Wash Basis Adjustment | AA5: Adjusted Total Cost | AB5: Adjusted Cost / Share | AC5: Loss Seq | AD5: Review Row #
A6: =IF('1_Data Entry'!$E6="","",IF(COUNTA('1_Data Entry'!C6:N6)=0,"",'1_Data Entry'!A6)) -> 1 | B6: =IF('1_Data Entry'!$E6="","",IF(A6="","",IF(S6<>"OK","Check row",IF(M6="","Open lot",IF(R6=0,"Closed lot","Partially sold"))))) -> Closed lot | C6: =IF(A6="","",'1_Data Entry'!C6) -> US | D6: =IF(A6="","",'1_Data Entry'!D6) -> MLP | E6: =IF(A6="","",'1_Data Entry'!E6) -> EPD | F6: =IF(E6="","",UPPER(TRIM(E6))) -> EPD | G6: =IF(F6="","",IFERROR(VLOOKUP(F6,'6_Reference Lists'!$A$4:$D$64,4,FALSE()),'1_Data Entry'!F6)) -> Enterprise Products Partners L.P. | H6: =IF('1_Data Entry'!$E6="","",IF(OR(F6="",I6="",J6="",K6=""),"",F6&"-"&TEXT(I6,"yyyymmdd")&"-"&SUBSTITUTE(TEXT(ROUND(J6,3),"0.###"),".","D")&"-"&SUBSTITUTE(TEXT(ROUND(K6,3),"0.###"),".","D"))) -> EPD-20240216-580D-27D25 | I6: =IF('1_Data Entry'!$E6="","",IF(A6="","",'1_Data Entry'!G6)) -> 45338 | J6: =IF('1_Data Entry'!$E6="","",IF(A6="","",'1_Data Entry'!H6)) -> 580 | K6: =IF('1_Data Entry'!$E6="","",IF(A6="","",'1_Data Entry'!I6)) -> 27.25 | L6: =IF('1_Data Entry'!$E6="","",IF(OR(J6="",K6=""),"",J6*K6)) -> 15805 | M6: =IF(A6="","",IF(OR('1_Data Entry'!L6="",'1_Data Entry'!L6<=0),"",'1_Data Entry'!J6)) -> 46090 | N6: =IF('1_Data Entry'!$E6="","",IF(OR(J6="",R6=""),"",MAX(J6-R6,0))) -> 580 | O6: =IF('1_Data Entry'!$E6="","",IF(A6="","",'1_Data Entry'!L6)) -> 38.15 | P6: =IF(OR(M6="",O6="",O6<=0,N6="",N6<=0),"",O6*N6) -> 22127 | Q6: =IF('1_Data Entry'!$E6="","",IF(OR(M6="",P6="",L6=""),"",P6-L6)) -> 6322 | R6: =IF(A6="","",IF('1_Data Entry'!M6<>"",'1_Data Entry'!M6,IF('1_Data Entry'!J6="",J6,""))) -> 0 | S6: =IF('1_Data Entry'!$E6="","",IF(A6="","",IF(OR(F6="",I6="",J6="",K6=""),"Check row",IF(AND(M6<>"",M6<I6),"Sell before buy",IF(AND(R6<>"",J6<R6),"Shares remaining exceeds buy",IF(AND(M6<>"",OR(O6="",O6<=0),N6>0),"Missing sale price","OK")))))) -> OK | T6: =IF('1_Data Entry'!$E6="","",IF(A6="","",IF(AND(Q6<0,M6<>""),"Yes","No"))) -> No | U6: =IF('1_Data Entry'!$E6="","",IF(OR(A6="",T6<>"Yes",M6=""),"No",IF(COUNTIFS($F$6:$F$505,F6,$I$6:$I$505,">="&M6-30,$I$6:$I$505,"<="&M6+30,$A$6:$A$505,"<>"&A6)>0,"Yes","No"))) -> No | V6: =IF('1_Data Entry'!$E6="","",IF(OR(A6="",U6<>"Yes",M6=""),"",M6+30)) | W6: =IF('1_Data Entry'!$E6="","",IF(A6="","",IF(S6="OK","Ready","Review row"))) -> Ready | X6: =IF(OR(I6="",M6=""),"",M6-I6) -> 752 | Y6: =IF(X6="","",IF(X6<=365,"Short-Term","Long-Term")) -> Long-Term | Z6: =IF('1_Data Entry'!$E6="","",SUM(SUMIFS('4_Wash Match Table'!R$7:R$500,'4_Wash Match Table'!L$7:L$500,H6),(SUMIFS('4_Wash Match Table'!AA$7:AA$500,'4_Wash Match Table'!U$7:U$500,H6)),(SUMIFS('4_Wash Match Table'!AJ$7:AJ$500,'4_Wash Match Table'!AD$7:AD$500,H6)),(SUMIFS('4_Wash Match Table'!AS$7:AS$500,'4_Wash Match Table'!AM$7:AM$500,H6)))) -> 0 | AA6: =IF('1_Data Entry'!$E6="","",IF(OR(L6="",Z6=""),"",L6+Z6)) -> 15805 | AB6: =IFERROR(IF(OR(J6="",AA6=""),"",AA6/J6),"") -> 27.25 | AC6: =IF(AND($M6<>"",$Q6<0),COUNTIFS($M$6:M6,"<>",$Q$6:Q6,"<0"),"") | AD6: =IF(A6="","",ROW()) -> 6
A7: =IF('1_Data Entry'!$E7="","",IF(COUNTA('1_Data Entry'!C7:N7)=0,"",'1_Data Entry'!A7)) -> 2 | B7: =IF('1_Data Entry'!$E7="","",IF(A7="","",IF(S7<>"OK","Check row",IF(M7="","Open lot",IF(R7=0,"Closed lot","Partially sold"))))) -> Closed lot | C7: =IF(A7="","",'1_Data Entry'!C7) -> US | D7: =IF(A7="","",'1_Data Entry'!D7) -> MLP | E7: =IF(A7="","",'1_Data Entry'!E7) -> EPD | F7: =IF(E7="","",UPPER(TRIM(E7))) -> EPD | G7: =IF(F7="","",IFERROR(VLOOKUP(F7,'6_Reference Lists'!$A$4:$D$64,4,FALSE()),'1_Data Entry'!F7)) -> Enterprise Products Partners L.P. | H7: =IF('1_Data Entry'!$E7="","",IF(OR(F7="",I7="",J7="",K7=""),"",F7&"-"&TEXT(I7,"yyyymmdd")&"-"&SUBSTITUTE(TEXT(ROUND(J7,3),"0.###"),".","D")&"-"&SUBSTITUTE(TEXT(ROUND(K7,3),"0.###"),".","D"))) -> EPD-20240216-615D-27D25 | I7: =IF('1_Data Entry'!$E7="","",IF(A7="","",'1_Data Entry'!G7)) -> 45338 | J7: =IF('1_Data Entry'!$E7="","",IF(A7="","",'1_Data Entry'!H7)) -> 615 | K7: =IF('1_Data Entry'!$E7="","",IF(A7="","",'1_Data Entry'!I7)) -> 27.25 | L7: =IF('1_Data Entry'!$E7="","",IF(OR(J7="",K7=""),"",J7*K7)) -> 16758.75 | M7: =IF(A7="","",IF(OR('1_Data Entry'!L7="",'1_Data Entry'!L7<=0),"",'1_Data Entry'!J7)) -> 46090 | N7: =IF('1_Data Entry'!$E7="","",IF(OR(J7="",R7=""),"",MAX(J7-R7,0))) -> 615 | O7: =IF('1_Data Entry'!$E7="","",IF(A7="","",'1_Data Entry'!L7)) -> 38.15 | P7: =IF(OR(M7="",O7="",O7<=0,N7="",N7<=0),"",O7*N7) -> 23462.25 | Q7: =IF('1_Data Entry'!$E7="","",IF(OR(M7="",P7="",L7=""),"",P7-L7)) -> 6703.5 | R7: =IF(A7="","",IF('1_Data Entry'!M7<>"",'1_Data Entry'!M7,IF('1_Data Entry'!J7="",J7,""))) -> 0 | S7: =IF('1_Data Entry'!$E7="","",IF(A7="","",IF(OR(F7="",I7="",J7="",K7=""),"Check row",IF(AND(M7<>"",M7<I7),"Sell before buy",IF(AND(R7<>"",J7<R7),"Shares remaining exceeds buy",IF(AND(M7<>"",OR(O7="",O7<=0),N7>0),"Missing sale price","OK")))))) -> OK | T7: =IF('1_Data Entry'!$E7="","",IF(A7="","",IF(AND(Q7<0,M7<>""),"Yes","No"))) -> No | U7: =IF('1_Data Entry'!$E7="","",IF(OR(A7="",T7<>"Yes",M7=""),"No",IF(COUNTIFS($F$6:$F$505,F7,$I$6:$I$505,">="&M7-30,$I$6:$I$505,"<="&M7+30,$A$6:$A$505,"<>"&A7)>0,"Yes","No"))) -> No | V7: =IF('1_Data Entry'!$E7="","",IF(OR(A7="",U7<>"Yes",M7=""),"",M7+30)) | W7: =IF('1_Data Entry'!$E7="","",IF(A7="","",IF(S7="OK","Ready","Review row"))) -> Ready | X7: =IF(OR(I7="",M7=""),"",M7-I7) -> 752 | Y7: =IF(X7="","",IF(X7<=365,"Short-Term","Long-Term")) -> Long-Term | Z7: =IF('1_Data Entry'!$E7="","",SUM(SUMIFS('4_Wash Match Table'!R$7:R$500,'4_Wash Match Table'!L$7:L$500,H7),(SUMIFS('4_Wash Match Table'!AA$7:AA$500,'4_Wash Match Table'!U$7:U$500,H7)),(SUMIFS('4_Wash Match Table'!AJ$7:AJ$500,'4_Wash Match Table'!AD$7:AD$500,H7)),(SUMIFS('4_Wash Match Table'!AS$7:AS$500,'4_Wash Match Table'!AM$7:AM$500,H7)))) -> 0 | AA7: =IF('1_Data Entry'!$E7="","",IF(OR(L7="",Z7=""),"",L7+Z7)) -> 16758.75 | AB7: =IFERROR(IF(OR(J7="",AA7=""),"",AA7/J7),"") -> 27.25 | AC7: =IF(AND($M7<>"",$Q7<0),COUNTIFS($M$6:M7,"<>",$Q$6:Q7,"<0"),"") | AD7: =IF(A7="","",ROW()) -> 7
A8: =IF('1_Data Entry'!$E8="","",IF(COUNTA('1_Data Entry'!C8:N8)=0,"",'1_Data Entry'!A8)) -> 3 | B8: =IF('1_Data Entry'!$E8="","",IF(A8="","",IF(S8<>"OK","Check row",IF(M8="","Open lot",IF(R8=0,"Closed lot","Partially sold"))))) -> Closed lot | C8: =IF(A8="","",'1_Data Entry'!C8) -> US | D8: =IF(A8="","",'1_Data Entry'!D8) -> MLP | E8: =IF(A8="","",'1_Data Entry'!E8) -> EPD | F8: =IF(E8="","",UPPER(TRIM(E8))) -> EPD | G8: =IF(F8="","",IFERROR(VLOOKUP(F8,'6_Reference Lists'!$A$4:$D$64,4,FALSE()),'1_Data Entry'!F8)) -> Enterprise Products Partners L.P. | H8: =IF('1_Data Entry'!$E8="","",IF(OR(F8="",I8="",J8="",K8=""),"",F8&"-"&TEXT(I8,"yyyymmdd")&"-"&SUBSTITUTE(TEXT(ROUND(J8,3),"0.###"),".","D")&"-"&SUBSTITUTE(TEXT(ROUND(K8,3),"0.###"),".","D"))) -> EPD-20250218-580D-33D72 | I8: =IF('1_Data Entry'!$E8="","",IF(A8="","",'1_Data Entry'!G8)) -> 45706 | J8: =IF('1_Data Entry'!$E8="","",IF(A8="","",'1_Data Entry'!H8)) -> 580 | K8: =IF('1_Data Entry'!$E8="","",IF(A8="","",'1_Data Entry'!I8)) -> 33.72 | L8: =IF('1_Data Entry'!$E8="","",IF(OR(J8="",K8=""),"",J8*K8)) -> 19557.6 | M8: =IF(A8="","",IF(OR('1_Data Entry'!L8="",'1_Data Entry'!L8<=0),"",'1_Data Entry'!J8)) -> 46090 | N8: =IF('1_Data Entry'!$E8="","",IF(OR(J8="",R8=""),"",MAX(J8-R8,0))) -> 580 | O8: =IF('1_Data Entry'!$E8="","",IF(A8="","",'1_Data Entry'!L8)) -> 38.15 | P8: =IF(OR(M8="",O8="",O8<=0,N8="",N8<=0),"",O8*N8) -> 22127 | Q8: =IF('1_Data Entry'!$E8="","",IF(OR(M8="",P8="",L8=""),"",P8-L8)) -> 2569.4 | R8: =IF(A8="","",IF('1_Data Entry'!M8<>"",'1_Data Entry'!M8,IF('1_Data Entry'!J8="",J8,""))) -> 0 | S8: =IF('1_Data Entry'!$E8="","",IF(A8="","",IF(OR(F8="",I8="",J8="",K8=""),"Check row",IF(AND(M8<>"",M8<I8),"Sell before buy",IF(AND(R8<>"",J8<R8),"Shares remaining exceeds buy",IF(AND(M8<>"",OR(O8="",O8<=0),N8>0),"Missing sale price","OK")))))) -> OK | T8: =IF('1_Data Entry'!$E8="","",IF(A8="","",IF(AND(Q8<0,M8<>""),"Yes","No"))) -> No | U8: =IF('1_Data Entry'!$E8="","",IF(OR(A8="",T8<>"Yes",M8=""),"No",IF(COUNTIFS($F$6:$F$505,F8,$I$6:$I$505,">="&M8-30,$I$6:$I$505,"<="&M8+30,$A$6:$A$505,"<>"&A8)>0,"Yes","No"))) -> No | V8: =IF('1_Data Entry'!$E8="","",IF(OR(A8="",U8<>"Yes",M8=""),"",M8+30)) | W8: =IF('1_Data Entry'!$E8="","",IF(A8="","",IF(S8="OK","Ready","Review row"))) -> Ready | X8: =IF(OR(I8="",M8=""),"",M8-I8) -> 384 | Y8: =IF(X8="","",IF(X8<=365,"Short-Term","Long-Term")) -> Long-Term | Z8: =IF('1_Data Entry'!$E8="","",SUM(SUMIFS('4_Wash Match Table'!R$7:R$500,'4_Wash Match Table'!L$7:L$500,H8),(SUMIFS('4_Wash Match Table'!AA$7:AA$500,'4_Wash Match Table'!U$7:U$500,H8)),(SUMIFS('4_Wash Match Table'!AJ$7:AJ$500,'4_Wash Match Table'!AD$7:AD$500,H8)),(SUMIFS('4_Wash Match Table'!AS$7:AS$500,'4_Wash Match Table'!AM$7:AM$500,H8)))) -> 0 | AA8: =IF('1_Data Entry'!$E8="","",IF(OR(L8="",Z8=""),"",L8+Z8)) -> 19557.6 | AB8: =IFERROR(IF(OR(J8="",AA8=""),"",AA8/J8),"") -> 33.72 | AC8: =IF(AND($M8<>"",$Q8<0),COUNTIFS($M$6:M8,"<>",$Q$6:Q8,"<0"),"") | AD8: =IF(A8="","",ROW()) -> 8
A9: =IF('1_Data Entry'!$E9="","",IF(COUNTA('1_Data Entry'!C9:N9)=0,"",'1_Data Entry'!A9)) -> 4 | B9: =IF('1_Data Entry'!$E9="","",IF(A9="","",IF(S9<>"OK","Check row",IF(M9="","Open lot",IF(R9=0,"Closed lot","Partially sold"))))) -> Closed lot | C9: =IF(A9="","",'1_Data Entry'!C9) -> US | D9: =IF(A9="","",'1_Data Entry'!D9) -> MLP | E9: =IF(A9="","",'1_Data Entry'!E9) -> EPD | F9: =IF(E9="","",UPPER(TRIM(E9))) -> EPD | G9: =IF(F9="","",IFERROR(VLOOKUP(F9,'6_Reference Lists'!$A$4:$D$64,4,FALSE()),'1_Data Entry'!F9)) -> Enterprise Products Partners L.P. | H9: =IF('1_Data Entry'!$E9="","",IF(OR(F9="",I9="",J9="",K9=""),"",F9&"-"&TEXT(I9,"yyyymmdd")&"-"&SUBSTITUTE(TEXT(ROUND(J9,3),"0.###"),".","D")&"-"&SUBSTITUTE(TEXT(ROUND(K9,3),"0.###"),".","D"))) -> EPD-20250218-30D-33D72 | I9: =IF('1_Data Entry'!$E9="","",IF(A9="","",'1_Data Entry'!G9)) -> 45706 | J9: =IF('1_Data Entry'!$E9="","",IF(A9="","",'1_Data Entry'!H9)) -> 30 | K9: =IF('1_Data Entry'!$E9="","",IF(A9="","",'1_Data Entry'!I9)) -> 33.72 | L9: =IF('1_Data Entry'!$E9="","",IF(OR(J9="",K9=""),"",J9*K9)) -> 1011.6 | M9: =IF(A9="","",IF(OR('1_Data Entry'!L9="",'1_Data Entry'!L9<=0),"",'1_Data Entry'!J9)) -> 46090 | N9: =IF('1_Data Entry'!$E9="","",IF(OR(J9="",R9=""),"",MAX(J9-R9,0))) -> 30 | O9: =IF('1_Data Entry'!$E9="","",IF(A9="","",'1_Data Entry'!L9)) -> 38 | P9: =IF(OR(M9="",O9="",O9<=0,N9="",N9<=0),"",O9*N9) -> 1140 | Q9: =IF('1_Data Entry'!$E9="","",IF(OR(M9="",P9="",L9=""),"",P9-L9)) -> 128.4 | R9: =IF(A9="","",IF('1_Data Entry'!M9<>"",'1_Data Entry'!M9,IF('1_Data Entry'!J9="",J9,""))) -> 0 | S9: =IF('1_Data Entry'!$E9="","",IF(A9="","",IF(OR(F9="",I9="",J9="",K9=""),"Check row",IF(AND(M9<>"",M9<I9),"Sell before buy",IF(AND(R9<>"",J9<R9),"Shares remaining exceeds buy",IF(AND(M9<>"",OR(O9="",O9<=0),N9>0),"Missing sale price","OK")))))) -> OK | T9: =IF('1_Data Entry'!$E9="","",IF(A9="","",IF(AND(Q9<0,M9<>""),"Yes","No"))) -> No | U9: =IF('1_Data Entry'!$E9="","",IF(OR(A9="",T9<>"Yes",M9=""),"No",IF(COUNTIFS($F$6:$F$505,F9,$I$6:$I$505,">="&M9-30,$I$6:$I$505,"<="&M9+30,$A$6:$A$505,"<>"&A9)>0,"Yes","No"))) -> No | V9: =IF('1_Data Entry'!$E9="","",IF(OR(A9="",U9<>"Yes",M9=""),"",M9+30)) | W9: =IF('1_Data Entry'!$E9="","",IF(A9="","",IF(S9="OK","Ready","Review row"))) -> Ready | X9: =IF(OR(I9="",M9=""),"",M9-I9) -> 384 | Y9: =IF(X9="","",IF(X9<=365,"Short-Term","Long-Term")) -> Long-Term | Z9: =IF('1_Data Entry'!$E9="","",SUM(SUMIFS('4_Wash Match Table'!R$7:R$500,'4_Wash Match Table'!L$7:L$500,H9),(SUMIFS('4_Wash Match Table'!AA$7:AA$500,'4_Wash Match Table'!U$7:U$500,H9)),(SUMIFS('4_Wash Match Table'!AJ$7:AJ$500,'4_Wash Match Table'!AD$7:AD$500,H9)),(SUMIFS('4_Wash Match Table'!AS$7:AS$500,'4_Wash Match Table'!AM$7:AM$500,H9)))) -> 0 | AA9: =IF('1_Data Entry'!$E9="","",IF(OR(L9="",Z9=""),"",L9+Z9)) -> 1011.6 | AB9: =IFERROR(IF(OR(J9="",AA9=""),"",AA9/J9),"") -> 33.72 | AC9: =IF(AND($M9<>"",$Q9<0),COUNTIFS($M$6:M9,"<>",$Q$6:Q9,"<0"),"") | AD9: =IF(A9="","",ROW()) -> 9
A10: =IF('1_Data Entry'!$E10="","",IF(COUNTA('1_Data Entry'!C10:N10)=0,"",'1_Data Entry'!A10)) -> 5 | B10: =IF('1_Data Entry'!$E10="","",IF(A10="","",IF(S10<>"OK","Check row",IF(M10="","Open lot",IF(R10=0,"Closed lot","Partially sold"))))) -> Closed lot | C10: =IF(A10="","",'1_Data Entry'!C10) -> US | D10: =IF(A10="","",'1_Data Entry'!D10) -> MLP | E10: =IF(A10="","",'1_Data Entry'!E10) -> EPD | F10: =IF(E10="","",UPPER(TRIM(E10))) -> EPD | G10: =IF(F10="","",IFERROR(VLOOKUP(F10,'6_Reference Lists'!$A$4:$D$64,4,FALSE()),'1_Data Entry'!F10)) -> Enterprise Products Partners L.P. | H10: =IF('1_Data Entry'!$E10="","",IF(OR(F10="",I10="",J10="",K10=""),"",F10&"-"&TEXT(I10,"yyyymmdd")&"-"&SUBSTITUTE(TEXT(ROUND(J10,3),"0.###"),".","D")&"-"&SUBSTITUTE(TEXT(ROUND(K10,3),"0.###"),".","D"))) -> EPD-20250218-585D-33D72 | I10: =IF('1_Data Entry'!$E10="","",IF(A10="","",'1_Data Entry'!G10)) -> 45706 | J10: =IF('1_Data Entry'!$E10="","",IF(A10="","",'1_Data Entry'!H10)) -> 585 | K10: =IF('1_Data Entry'!$E10="","",IF(A10="","",'1_Data Entry'!I10)) -> 33.72 | L10: =IF('1_Data Entry'!$E10="","",IF(OR(J10="",K10=""),"",J10*K10)) -> 19726.2 | M10: =IF(A10="","",IF(OR('1_Data Entry'!L10="",'1_Data Entry'!L10<=0),"",'1_Data Entry'!J10)) -> 46090 | N10: =IF('1_Data Entry'!$E10="","",IF(OR(J10="",R10=""),"",MAX(J10-R10,0))) -> 585 | O10: =IF('1_Data Entry'!$E10="","",IF(A10="","",'1_Data Entry'!L10)) -> 38 | P10: =IF(OR(M10="",O10="",O10<=0,N10="",N10<=0),"",O10*N10) -> 22230 | Q10: =IF('1_Data Entry'!$E10="","",IF(OR(M10="",P10="",L10=""),"",P10-L10)) -> 2503.8 | R10: =IF(A10="","",IF('1_Data Entry'!M10<>"",'1_Data Entry'!M10,IF('1_Data Entry'!J10="",J10,""))) -> 0 | S10: =IF('1_Data Entry'!$E10="","",IF(A10="","",IF(OR(F10="",I10="",J10="",K10=""),"Check row",IF(AND(M10<>"",M10<I10),"Sell before buy",IF(AND(R10<>"",J10<R10),"Shares remaining exceeds buy",IF(AND(M10<>"",OR(O10="",O10<=0),N10>0),"Missing sale price","OK")))))) -> OK | T10: =IF('1_Data Entry'!$E10="","",IF(A10="","",IF(AND(Q10<0,M10<>""),"Yes","No"))) -> No | U10: =IF('1_Data Entry'!$E10="","",IF(OR(A10="",T10<>"Yes",M10=""),"No",IF(COUNTIFS($F$6:$F$505,F10,$I$6:$I$505,">="&M10-30,$I$6:$I$505,"<="&M10+30,$A$6:$A$505,"<>"&A10)>0,"Yes","No"))) -> No | V10: =IF('1_Data Entry'!$E10="","",IF(OR(A10="",U10<>"Yes",M10=""),"",M10+30)) | W10: =IF('1_Data Entry'!$E10="","",IF(A10="","",IF(S10="OK","Ready","Review row"))) -> Ready | X10: =IF(OR(I10="",M10=""),"",M10-I10) -> 384 | Y10: =IF(X10="","",IF(X10<=365,"Short-Term","Long-Term")) -> Long-Term | Z10: =IF('1_Data Entry'!$E10="","",SUM(SUMIFS('4_Wash Match Table'!R$7:R$500,'4_Wash Match Table'!L$7:L$500,H10),(SUMIFS('4_Wash Match Table'!AA$7:AA$500,'4_Wash Match Table'!U$7:U$500,H10)),(SUMIFS('4_Wash Match Table'!AJ$7:AJ$500,'4_Wash Match Table'!AD$7:AD$500,H10)),(SUMIFS('4_Wash Match Table'!AS$7:AS$500,'4_Wash Match Table'!AM$7:AM$500,H10)))) -> 0 | AA10: =IF('1_Data Entry'!$E10="","",IF(OR(L10="",Z10=""),"",L10+Z10)) -> 19726.2 | AB10: =IFERROR(IF(OR(J10="",AA10=""),"",AA10/J10),"") -> 33.72 | AC10: =IF(AND($M10<>"",$Q10<0),COUNTIFS($M$6:M10,"<>",$Q$6:Q10,"<0"),"") | AD10: =IF(A10="","",ROW()) -> 10
A11: =IF('1_Data Entry'!$E11="","",IF(COUNTA('1_Data Entry'!C11:N11)=0,"",'1_Data Entry'!A11)) -> 6 | B11: =IF('1_Data Entry'!$E11="","",IF(A11="","",IF(S11<>"OK","Check row",IF(M11="","Open lot",IF(R11=0,"Closed lot","Partially sold"))))) -> Closed lot | C11: =IF(A11="","",'1_Data Entry'!C11) -> US | D11: =IF(A11="","",'1_Data Entry'!D11) -> MLP | E11: =IF(A11="","",'1_Data Entry'!E11) -> EPD | F11: =IF(E11="","",UPPER(TRIM(E11))) -> EPD | G11: =IF(F11="","",IFERROR(VLOOKUP(F11,'6_Reference Lists'!$A$4:$D$64,4,FALSE()),'1_Data Entry'!F11)) -> Enterprise Products Partners L.P. | H11: =IF('1_Data Entry'!$E11="","",IF(OR(F11="",I11="",J11="",K11=""),"",F11&"-"&TEXT(I11,"yyyymmdd")&"-"&SUBSTITUTE(TEXT(ROUND(J11,3),"0.###"),".","D")&"-"&SUBSTITUTE(TEXT(ROUND(K11,3),"0.###"),".","D"))) -> EPD-20250218-562D-33D72 | I11: =IF('1_Data Entry'!$E11="","",IF(A11="","",'1_Data Entry'!G11)) -> 45706 | J11: =IF('1_Data Entry'!$E11="","",IF(A11="","",'1_Data Entry'!H11)) -> 562 | K11: =IF('1_Data Entry'!$E11="","",IF(A11="","",'1_Data Entry'!I11)) -> 33.72 | L11: =IF('1_Data Entry'!$E11="","",IF(OR(J11="",K11=""),"",J11*K11)) -> 18950.64 | M11: =IF(A11="","",IF(OR('1_Data Entry'!L11="",'1_Data Entry'!L11<=0),"",'1_Data Entry'!J11)) -> 46090 | N11: =IF('1_Data Entry'!$E11="","",IF(OR(J11="",R11=""),"",MAX(J11-R11,0))) -> 562 | O11: =IF('1_Data Entry'!$E11="","",IF(A11="","",'1_Data Entry'!L11)) -> 38 | P11: =IF(OR(M11="",O11="",O11<=0,N11="",N11<=0),"",O11*N11) -> 21356 | Q11: =IF('1_Data Entry'!$E11="","",IF(OR(M11="",P11="",L11=""),"",P11-L11)) -> 2405.36 | R11: =IF(A11="","",IF('1_Data Entry'!M11<>"",'1_Data Entry'!M11,IF('1_Data Entry'!J11="",J11,""))) -> 0 | S11: =IF('1_Data Entry'!$E11="","",IF(A11="","",IF(OR(F11="",I11="",J11="",K11=""),"Check row",IF(AND(M11<>"",M11<I11),"Sell before buy",IF(AND(R11<>"",J11<R11),"Shares remaining exceeds buy",IF(AND(M11<>"",OR(O11="",O11<=0),N11>0),"Missing sale price","OK")))))) -> OK | T11: =IF('1_Data Entry'!$E11="","",IF(A11="","",IF(AND(Q11<0,M11<>""),"Yes","No"))) -> No | U11: =IF('1_Data Entry'!$E11="","",IF(OR(A11="",T11<>"Yes",M11=""),"No",IF(COUNTIFS($F$6:$F$505,F11,$I$6:$I$505,">="&M11-30,$I$6:$I$505,"<="&M11+30,$A$6:$A$505,"<>"&A11)>0,"Yes","No"))) -> No | V11: =IF('1_Data Entry'!$E11="","",IF(OR(A11="",U11<>"Yes",M11=""),"",M11+30)) | W11: =IF('1_Data Entry'!$E11="","",IF(A11="","",IF(S11="OK","Ready","Review row"))) -> Ready | X11: =IF(OR(I11="",M11=""),"",M11-I11) -> 384 | Y11: =IF(X11="","",IF(X11<=365,"Short-Term","Long-Term")) -> Long-Term | Z11: =IF('1_Data Entry'!$E11="","",SUM(SUMIFS('4_Wash Match Table'!R$7:R$500,'4_Wash Match Table'!L$7:L$500,H11),(SUMIFS('4_Wash Match Table'!AA$7:AA$500,'4_Wash Match Table'!U$7:U$500,H11)),(SUMIFS('4_Wash Match Table'!AJ$7:AJ$500,'4_Wash Match Table'!AD$7:AD$500,H11)),(SUMIFS('4_Wash Match Table'!AS$7:AS$500,'4_Wash Match Table'!AM$7:AM$500,H11)))) -> 0 | AA11: =IF('1_Data Entry'!$E11="","",IF(OR(L11="",Z11=""),"",L11+Z11)) -> 18950.64 | AB11: =IFERROR(IF(OR(J11="",AA11=""),"",AA11/J11),"") -> 33.72 | AC11: =IF(AND($M11<>"",$Q11<0),COUNTIFS($M$6:M11,"<>",$Q$6:Q11,"<0"),"") | AD11: =IF(A11="","",ROW()) -> 11
A12: =IF('1_Data Entry'!$E12="","",IF(COUNTA('1_Data Entry'!C12:N12)=0,"",'1_Data Entry'!A12)) -> 7 | B12: =IF('1_Data Entry'!$E12="","",IF(A12="","",IF(S12<>"OK","Check row",IF(M12="","Open lot",IF(R12=0,"Closed lot","Partially sold"))))) -> Closed lot | C12: =IF(A12="","",'1_Data Entry'!C12) -> US | D12: =IF(A12="","",'1_Data Entry'!D12) -> MLP | E12: =IF(A12="","",'1_Data Entry'!E12) -> EPD | F12: =IF(E12="","",UPPER(TRIM(E12))) -> EPD | G12: =IF(F12="","",IFERROR(VLOOKUP(F12,'6_Reference Lists'!$A$4:$D$64,4,FALSE()),'1_Data Entry'!F12)) -> Enterprise Products Partners L.P. | H12: =IF('1_Data Entry'!$E12="","",IF(OR(F12="",I12="",J12="",K12=""),"",F12&"-"&TEXT(I12,"yyyymmdd")&"-"&SUBSTITUTE(TEXT(ROUND(J12,3),"0.###"),".","D")&"-"&SUBSTITUTE(TEXT(ROUND(K12,3),"0.###"),".","D"))) -> EPD-20250218-580D-33D72 | I12: =IF('1_Data Entry'!$E12="","",IF(A12="","",'1_Data Entry'!G12)) -> 45706 | J12: =IF('1_Data Entry'!$E12="","",IF(A12="","",'1_Data Entry'!H12)) -> 580 | K12: =IF('1_Data Entry'!$E12="","",IF(A12="","",'1_Data Entry'!I12)) -> 33.72 | L12: =IF('1_Data Entry'!$E12="","",IF(OR(J12="",K12=""),"",J12*K12)) -> 19557.6 | M12: =IF(A12="","",IF(OR('1_Data Entry'!L12="",'1_Data Entry'!L12<=0),"",'1_Data Entry'!J12)) -> 46090 | N12: =IF('1_Data Entry'!$E12="","",IF(OR(J12="",R12=""),"",MAX(J12-R12,0))) -> 580 | O12: =IF('1_Data Entry'!$E12="","",IF(A12="","",'1_Data Entry'!L12)) -> 38 | P12: =IF(OR(M12="",O12="",O12<=0,N12="",N12<=0),"",O12*N12) -> 22040 | Q12: =IF('1_Data Entry'!$E12="","",IF(OR(M12="",P12="",L12=""),"",P12-L12)) -> 2482.4 | R12: =IF(A12="","",IF('1_Data Entry'!M12<>"",'1_Data Entry'!M12,IF('1_Data Entry'!J12="",J12,""))) -> 0 | S12: =IF('1_Data Entry'!$E12="","",IF(A12="","",IF(OR(F12="",I12="",J12="",K12=""),"Check row",IF(AND(M12<>"",M12<I12),"Sell before buy",IF(AND(R12<>"",J12<R12),"Shares remaining exceeds buy",IF(AND(M12<>"",OR(O12="",O12<=0),N12>0),"Missing sale price","OK")))))) -> OK | T12: =IF('1_Data Entry'!$E12="","",IF(A12="","",IF(AND(Q12<0,M12<>""),"Yes","No"))) -> No | U12: =IF('1_Data Entry'!$E12="","",IF(OR(A12="",T12<>"Yes",M12=""),"No",IF(COUNTIFS($F$6:$F$505,F12,$I$6:$I$505,">="&M12-30,$I$6:$I$505,"<="&M12+30,$A$6:$A$505,"<>"&A12)>0,"Yes","No"))) -> No | V12: =IF('1_Data Entry'!$E12="","",IF(OR(A12="",U12<>"Yes",M12=""),"",M12+30)) | W12: =IF('1_Data Entry'!$E12="","",IF(A12="","",IF(S12="OK","Ready","Review row"))) -> Ready | X12: =IF(OR(I12="",M12=""),"",M12-I12) -> 384 | Y12: =IF(X12="","",IF(X12<=365,"Short-Term","Long-Term")) -> Long-Term | Z12: =IF('1_Data Entry'!$E12="","",SUM(SUMIFS('4_Wash Match Table'!R$7:R$500,'4_Wash Match Table'!L$7:L$500,H12),(SUMIFS('4_Wash Match Table'!AA$7:AA$500,'4_Wash Match Table'!U$7:U$500,H12)),(SUMIFS('4_Wash Match Table'!AJ$7:AJ$500,'4_Wash Match Table'!AD$7:AD$500,H12)),(SUMIFS('4_Wash Match Table'!AS$7:AS$500,'4_Wash Match Table'!AM$7:AM$500,H12)))) -> 0 | AA12: =IF('1_Data Entry'!$E12="","",IF(OR(L12="",Z12=""),"",L12+Z12)) -> 19557.6 | AB12: =IFERROR(IF(OR(J12="",AA12=""),"",AA12/J12),"") -> 33.72 | AC12: =IF(AND($M12<>"",$Q12<0),COUNTIFS($M$6:M12,"<>",$Q$6:Q12,"<0"),"") | AD12: =IF(A12="","",ROW()) -> 12
A13: =IF('1_Data Entry'!$E13="","",IF(COUNTA('1_Data Entry'!C13:N13)=0,"",'1_Data Entry'!A13)) -> 8 | B13: =IF('1_Data Entry'!$E13="","",IF(A13="","",IF(S13<>"OK","Check row",IF(M13="","Open lot",IF(R13=0,"Closed lot","Partially sold"))))) -> Closed lot | C13: =IF(A13="","",'1_Data Entry'!C13) -> US | D13: =IF(A13="","",'1_Data Entry'!D13) -> MLP | E13: =IF(A13="","",'1_Data Entry'!E13) -> EPD | F13: =IF(E13="","",UPPER(TRIM(E13))) -> EPD | G13: =IF(F13="","",IFERROR(VLOOKUP(F13,'6_Reference Lists'!$A$4:$D$64,4,FALSE()),'1_Data Entry'!F13)) -> Enterprise Products Partners L.P. | H13: =IF('1_Data Entry'!$E13="","",IF(OR(F13="",I13="",J13="",K13=""),"",F13&"-"&TEXT(I13,"yyyymmdd")&"-"&SUBSTITUTE(TEXT(ROUND(J13,3),"0.###"),".","D")&"-"&SUBSTITUTE(TEXT(ROUND(K13,3),"0.###"),".","D"))) -> EPD-20240216-580D-27D25 | I13: =IF('1_Data Entry'!$E13="","",IF(A13="","",'1_Data Entry'!G13)) -> 45338 | J13: =IF('1_Data Entry'!$E13="","",IF(A13="","",'1_Data Entry'!H13)) -> 580 | K13: =IF('1_Data Entry'!$E13="","",IF(A13="","",'1_Data Entry'!I13)) -> 27.25 | L13: =IF('1_Data Entry'!$E13="","",IF(OR(J13="",K13=""),"",J13*K13)) -> 15805 | M13: =IF(A13="","",IF(OR('1_Data Entry'!L13="",'1_Data Entry'!L13<=0),"",'1_Data Entry'!J13)) -> 46098 | N13: =IF('1_Data Entry'!$E13="","",IF(OR(J13="",R13=""),"",MAX(J13-R13,0))) -> 580 | O13: =IF('1_Data Entry'!$E13="","",IF(A13="","",'1_Data Entry'!L13)) -> 37.79 | P13: =IF(OR(M13="",O13="",O13<=0,N13="",N13<=0),"",O13*N13) -> 21918.2 | Q13: =IF('1_Data Entry'!$E13="","",IF(OR(M13="",P13="",L13=""),"",P13-L13)) -> 6113.2 | R13: =IF(A13="","",IF('1_Data Entry'!M13<>"",'1_Data Entry'!M13,IF('1_Data Entry'!J13="",J13,""))) -> 0 | S13: =IF('1_Data Entry'!$E13="","",IF(A13="","",IF(OR(F13="",I13="",J13="",K13=""),"Check row",IF(AND(M13<>"",M13<I13),"Sell before buy",IF(AND(R13<>"",J13<R13),"Shares remaining exceeds buy",IF(AND(M13<>"",OR(O13="",O13<=0),N13>0),"Missing sale price","OK")))))) -> OK | T13: =IF('1_Data Entry'!$E13="","",IF(A13="","",IF(AND(Q13<0,M13<>""),"Yes","No"))) -> No | U13: =IF('1_Data Entry'!$E13="","",IF(OR(A13="",T13<>"Yes",M13=""),"No",IF(COUNTIFS($F$6:$F$505,F13,$I$6:$I$505,">="&M13-30,$I$6:$I$505,"<="&M13+30,$A$6:$A$505,"<>"&A13)>0,"Yes","No"))) -> No | V13: =IF('1_Data Entry'!$E13="","",IF(OR(A13="",U13<>"Yes",M13=""),"",M13+30)) | W13: =IF('1_Data Entry'!$E13="","",IF(A13="","",IF(S13="OK","Ready","Review row"))) -> Ready | X13: =IF(OR(I13="",M13=""),"",M13-I13) -> 760 | Y13: =IF(X13="","",IF(X13<=365,"Short-Term","Long-Term")) -> Long-Term | Z13: =IF('1_Data Entry'!$E13="","",SUM(SUMIFS('4_Wash Match Table'!R$7:R$500,'4_Wash Match Table'!L$7:L$500,H13),(SUMIFS('4_Wash Match Table'!AA$7:AA$500,'4_Wash Match Table'!U$7:U$500,H13)),(SUMIFS('4_Wash Match Table'!AJ$7:AJ$500,'4_Wash Match Table'!AD$7:AD$500,H13)),(SUMIFS('4_Wash Match Table'!AS$7:AS$500,'4_Wash Match Table'!AM$7:AM$500,H13)))) -> 0 | AA13: =IF('1_Data Entry'!$E13="","",IF(OR(L13="",Z13=""),"",L13+Z13)) -> 15805 | AB13: =IFERROR(IF(OR(J13="",AA13=""),"",AA13/J13),"") -> 27.25 | AC13: =IF(AND($M13<>"",$Q13<0),COUNTIFS($M$6:M13,"<>",$Q$6:Q13,"<0"),"") | AD13: =IF(A13="","",ROW()) -> 13
A14: =IF('1_Data Entry'!$E14="","",IF(COUNTA('1_Data Entry'!C14:N14)=0,"",'1_Data Entry'!A14)) -> 9 | B14: =IF('1_Data Entry'!$E14="","",IF(A14="","",IF(S14<>"OK","Check row",IF(M14="","Open lot",IF(R14=0,"Closed lot","Partially sold"))))) -> Closed lot | C14: =IF(A14="","",'1_Data Entry'!C14) -> US | D14: =IF(A14="","",'1_Data Entry'!D14) -> MLP | E14: =IF(A14="","",'1_Data Entry'!E14) -> EPD | F14: =IF(E14="","",UPPER(TRIM(E14))) -> EPD | G14: =IF(F14="","",IFERROR(VLOOKUP(F14,'6_Reference Lists'!$A$4:$D$64,4,FALSE()),'1_Data Entry'!F14)) -> Enterprise Products Partners L.P. | H14: =IF('1_Data Entry'!$E14="","",IF(OR(F14="",I14="",J14="",K14=""),"",F14&"-"&TEXT(I14,"yyyymmdd")&"-"&SUBSTITUTE(TEXT(ROUND(J14,3),"0.###"),".","D")&"-"&SUBSTITUTE(TEXT(ROUND(K14,3),"0.###"),".","D"))) -> EPD-20240216-351D-27D25 | I14: =IF('1_Data Entry'!$E14="","",IF(A14="","",'1_Data Entry'!G14)) -> 45338 | J14: =IF('1_Data Entry'!$E14="","",IF(A14="","",'1_Data Entry'!H14)) -> 351 | K14: =IF('1_Data Entry'!$E14="","",IF(A14="","",'1_Data Entry'!I14)) -> 27.25 | L14: =IF('1_Data Entry'!$E14="","",IF(OR(J14="",K14=""),"",J14*K14)) -> 9564.75 | M14: =IF(A14="","",IF(OR('1_Data Entry'!L14="",'1_Data Entry'!L14<=0),"",'1_Data Entry'!J14)) -> 46098 | N14: =IF('1_Data Entry'!$E14="","",IF(OR(J14="",R14=""),"",MAX(J14-R14,0))) -> 351 | O14: =IF('1_Data Entry'!$E14="","",IF(A14="","",'1_Data Entry'!L14)) -> 37.79 | P14: =IF(OR(M14="",O14="",O14<=0,N14="",N14<=0),"",O14*N14) -> 13264.29 | Q14: =IF('1_Data Entry'!$E14="","",IF(OR(M14="",P14="",L14=""),"",P14-L14)) -> 3699.54 | R14: =IF(A14="","",IF('1_Data Entry'!M14<>"",'1_Data Entry'!M14,IF('1_Data Entry'!J14="",J14,""))) -> 0 | S14: =IF('1_Data Entry'!$E14="","",IF(A14="","",IF(OR(F14="",I14="",J14="",K14=""),"Check row",IF(AND(M14<>"",M14<I14),"Sell before buy",IF(AND(R14<>"",J14<R14),"Shares remaining exceeds buy",IF(AND(M14<>"",OR(O14="",O14<=0),N14>0),"Missing sale price","OK")))))) -> OK | T14: =IF('1_Data Entry'!$E14="","",IF(A14="","",IF(AND(Q14<0,M14<>""),"Yes","No"))) -> No | U14: =IF('1_Data Entry'!$E14="","",IF(OR(A14="",T14<>"Yes",M14=""),"No",IF(COUNTIFS($F$6:$F$505,F14,$I$6:$I$505,">="&M14-30,$I$6:$I$505,"<="&M14+30,$A$6:$A$505,"<>"&A14)>0,"Yes","No"))) -> No | V14: =IF('1_Data Entry'!$E14="","",IF(OR(A14="",U14<>"Yes",M14=""),"",M14+30)) | W14: =IF('1_Data Entry'!$E14="","",IF(A14="","",IF(S14="OK","Ready","Review row"))) -> Ready | X14: =IF(OR(I14="",M14=""),"",M14-I14) -> 760 | Y14: =IF(X14="","",IF(X14<=365,"Short-Term","Long-Term")) -> Long-Term | Z14: =IF('1_Data Entry'!$E14="","",SUM(SUMIFS('4_Wash Match Table'!R$7:R$500,'4_Wash Match Table'!L$7:L$500,H14),(SUMIFS('4_Wash Match Table'!AA$7:AA$500,'4_Wash Match Table'!U$7:U$500,H14)),(SUMIFS('4_Wash Match Table'!AJ$7:AJ$500,'4_Wash Match Table'!AD$7:AD$500,H14)),(SUMIFS('4_Wash Match Table'!AS$7:AS$500,'4_Wash Match Table'!AM$7:AM$500,H14)))) -> 0 | AA14: =IF('1_Data Entry'!$E14="","",IF(OR(L14="",Z14=""),"",L14+Z14)) -> 9564.75 | AB14: =IFERROR(IF(OR(J14="",AA14=""),"",AA14/J14),"") -> 27.25 | AC14: =IF(AND($M14<>"",$Q14<0),COUNTIFS($M$6:M14,"<>",$Q$6:Q14,"<0"),"") | AD14: =IF(A14="","",ROW()) -> 14
A15: =IF('1_Data Entry'!$E15="","",IF(COUNTA('1_Data Entry'!C15:N15)=0,"",'1_Data Entry'!A15)) -> 10 | B15: =IF('1_Data Entry'!$E15="","",IF(A15="","",IF(S15<>"OK","Check row",IF(M15="","Open lot",IF(R15=0,"Closed lot","Partially sold"))))) -> Closed lot | C15: =IF(A15="","",'1_Data Entry'!C15) -> US | D15: =IF(A15="","",'1_Data Entry'!D15) -> ETF | E15: =IF(A15="","",'1_Data Entry'!E15) -> ITOT | F15: =IF(E15="","",UPPER(TRIM(E15))) -> ITOT | G15: =IF(F15="","",IFERROR(VLOOKUP(F15,'6_Reference Lists'!$A$4:$D$64,4,FALSE()),'1_Data Entry'!F15)) -> iShares Core S&P Total U.S. Stock Market ETF | H15: =IF('1_Data Entry'!$E15="","",IF(OR(F15="",I15="",J15="",K15=""),"",F15&"-"&TEXT(I15,"yyyymmdd")&"-"&SUBSTITUTE(TEXT(ROUND(J15,3),"0.###"),".","D")&"-"&SUBSTITUTE(TEXT(ROUND(K15,3),"0.###"),".","D"))) -> ITOT-20260317-0D883-150D63 | I15: =IF('1_Data Entry'!$E15="","",IF(A15="","",'1_Data Entry'!G15)) -> 46098 | J15: =IF('1_Data Entry'!$E15="","",IF(A15="","",'1_Data Entry'!H15)) -> 0.883 | K15: =IF('1_Data Entry'!$E15="","",IF(A15="","",'1_Data Entry'!I15)) -> 150.63 | L15: =IF('1_Data Entry'!$E15="","",IF(OR(J15="",K15=""),"",J15*K15)) -> 133.00629 | M15: =IF(A15="","",IF(OR('1_Data Entry'!L15="",'1_Data Entry'!L15<=0),"",'1_Data Entry'!J15)) -> 46101 | N15: =IF('1_Data Entry'!$E15="","",IF(OR(J15="",R15=""),"",MAX(J15-R15,0))) -> 0.883 | O15: =IF('1_Data Entry'!$E15="","",IF(A15="","",'1_Data Entry'!L15)) -> 142.93 | P15: =IF(OR(M15="",O15="",O15<=0,N15="",N15<=0),"",O15*N15) -> 126.20719 | Q15: =IF('1_Data Entry'!$E15="","",IF(OR(M15="",P15="",L15=""),"",P15-L15)) -> -6.7991 | R15: =IF(A15="","",IF('1_Data Entry'!M15<>"",'1_Data Entry'!M15,IF('1_Data Entry'!J15="",J15,""))) -> 0 | S15: =IF('1_Data Entry'!$E15="","",IF(A15="","",IF(OR(F15="",I15="",J15="",K15=""),"Check row",IF(AND(M15<>"",M15<I15),"Sell before buy",IF(AND(R15<>"",J15<R15),"Shares remaining exceeds buy",IF(AND(M15<>"",OR(O15="",O15<=0),N15>0),"Missing sale price","OK")))))) -> OK | T15: =IF('1_Data Entry'!$E15="","",IF(A15="","",IF(AND(Q15<0,M15<>""),"Yes","No"))) -> Yes | U15: =IF('1_Data Entry'!$E15="","",IF(OR(A15="",T15<>"Yes",M15=""),"No",IF(COUNTIFS($F$6:$F$505,F15,$I$6:$I$505,">="&M15-30,$I$6:$I$505,"<="&M15+30,$A$6:$A$505,"<>"&A15)>0,"Yes","No"))) -> Yes | V15: =IF('1_Data Entry'!$E15="","",IF(OR(A15="",U15<>"Yes",M15=""),"",M15+30)) -> 46131 | W15: =IF('1_Data Entry'!$E15="","",IF(A15="","",IF(S15="OK","Ready","Review row"))) -> Ready | X15: =IF(OR(I15="",M15=""),"",M15-I15) -> 3 | Y15: =IF(X15="","",IF(X15<=365,"Short-Term","Long-Term")) -> Short-Term | Z15: =IF('1_Data Entry'!$E15="","",SUM(SUMIFS('4_Wash Match Table'!R$7:R$500,'4_Wash Match Table'!L$7:L$500,H15),(SUMIFS('4_Wash Match Table'!AA$7:AA$500,'4_Wash Match Table'!U$7:U$500,H15)),(SUMIFS('4_Wash Match Table'!AJ$7:AJ$500,'4_Wash Match Table'!AD$7:AD$500,H15)),(SUMIFS('4_Wash Match Table'!AS$7:AS$500,'4_Wash Match Table'!AM$7:AM$500,H15)))) -> 0 | AA15: =IF('1_Data Entry'!$E15="","",IF(OR(L15="",Z15=""),"",L15+Z15)) -> 133.00629 | AB15: =IFERROR(IF(OR(J15="",AA15=""),"",AA15/J15),"") -> 150.63 | AC15: =IF(AND($M15<>"",$Q15<0),COUNTIFS($M$6:M15,"<>",$Q$6:Q15,"<0"),"") -> 1 | AD15: =IF(A15="","",ROW()) -> 15
